Workbook

Sheet Active_Ranges
A1: name | B1: sheet_id | C1: sheet_name | D1: ref_a1 | E1: first_cell | F1: last_cell | G1: n_rows | H1: n_cols | I1: n_cells | J1: is_active
A2: ACCH | B2: 17 | C2: World Cost tables | D2: ='World Cost tables'!$I$5 -> 0 | E2: I5 | F2: I5 | G2: 1 | H2: 1 | I2: 1 | J2: 1
A3: ACLH | B3: 17 | C3: World Cost tables | D3: ='World Cost tables'!$I$3 -> 0 | E3: I3 | F3: I3 | G3: 1 | H3: 1 | I3: 1 | J3: 1
A4: AECH | B4: 17 | C4: World Cost tables | D4: ='World Cost tables'!$K$5 -> 0 | E4: K5 | F4: K5 | G4: 1 | H4: 1 | I4: 1 | J4: 1
A5: AELH | B5: 17 | C5: World Cost tables | D5: ='World Cost tables'!$K$3 -> 0 | E5: K3 | F5: K3 | G5: 1 | H5: 1 | I5: 1 | J5: 1
A6: Aeroderivative_QTY | B6: 3 | C6: Data Entry | D6: ='Data Entry'!$E$85 -> 0 | E6: E85 | F6: E85 | G6: 1 | H6: 1 | I6: 1 | J6: 1
A7: ALG_Currency | B7: 19 | C7: World Currency Table | D7: ='World Currency Table'!$D$5 -> 0 | E7: D5 | F7: D5 | G7: 1 | H7: 1 | I7: 1 | J7: 1
A8: ALLOWANCE_FAT | B8: 17 | C8: World Cost tables | D8: ='World Cost tables'!$V$8 -> 0 | E8: V8 | F8: V8 | G8: 1 | H8: 1 | I8: 1 | J8: 1
A9: ALLOWANCE_HIGHRISK | B9: 17 | C9: World Cost tables | D9: ='World Cost tables'!$V$10 -> 0 | E9: V10 | F9: V10 | G9: 1 | H9: 1 | I9: 1 | J9: 1
A10: ALLOWANCE_PCT_COST | B10: 4 | C10: Application Based | D10: ='Application Based'!$E$458 -> 0 | E10: E458 | F10: E458 | G10: 1 | H10: 1 | I10: 1 | J10: 1
A11: ALLOWANCE_SITE | B11: 17 | C11: World Cost tables | D11: ='World Cost tables'!$V$9 -> 0 | E11: V9 | F11: V9 | G11: 1 | H11: 1 | I11: 1 | J11: 1
A12: ALLOWANCE_TOTAL_COST | B12: 14 | C12: Price Make-up | D12: ='Price Make-up'!$L$271 -> 0 | E12: L271 | F12: L271 | G12: 1 | H12: 1 | I12: 1 | J12: 1
A13: APP_1_AVG_RATE | B13: 14 | C13: Price Make-up | D13: ='Price Make-up'!$CT$132 -> 0 | E13: CT132 | F13: CT132 | G13: 1 | H13: 1 | I13: 1 | J13: 1
A14: APP_1_HOURS | B14: 3 | C14: Data Entry | D14: ='Data Entry'!$E$118 -> 0 | E14: E118 | F14: E118 | G14: 1 | H14: 1 | I14: 1 | J14: 1
A15: APP_1_HOURS_TUNED | B15: 15 | C15: Industry | D15: =Industry!$D$68 -> 0 | E15: D68 | F15: D68 | G15: 1 | H15: 1 | I15: 1 | J15: 1
A16: APP_1_HOURS_UNITS | B16: 3 | C16: Data Entry | D16: ='Data Entry'!$F$118 -> 0 | E16: F118 | F16: F118 | G16: 1 | H16: 1 | I16: 1 | J16: 1
A17: APP_1_NAME | B17: 3 | C17: Data Entry | D17: ='Data Entry'!$D$118 -> 0 | E17: D118 | F17: D118 | G17: 1 | H17: 1 | I17: 1 | J17: 1
A18: APP_1_NAME_TUNED | B18: 15 | C18: Industry | D18: =Industry!$D$67 -> 0 | E18: D67 | F18: D67 | G18: 1 | H18: 1 | I18: 1 | J18: 1
A19: APP_2_AVG_RATE | B19: 14 | C19: Price Make-up | D19: ='Price Make-up'!$CT$133 -> 0 | E19: CT133 | F19: CT133 | G19: 1 | H19: 1 | I19: 1 | J19: 1
A20: APP_2_HOURS | B20: 3 | C20: Data Entry | D20: ='Data Entry'!$E$119 -> 0 | E20: E119 | F20: E119 | G20: 1 | H20: 1 | I20: 1 | J20: 1
A21: APP_2_HOURS_TUNED | B21: 15 | C21: Industry | D21: =Industry!$D$70 -> 0 | E21: D70 | F21: D70 | G21: 1 | H21: 1 | I21: 1 | J21: 1
A22: APP_2_HOURS_UNITS | B22: 3 | C22: Data Entry | D22: ='Data Entry'!$F$119 -> 0 | E22: F119 | F22: F119 | G22: 1 | H22: 1 | I22: 1 | J22: 1
A23: APP_2_NAME | B23: 3 | C23: Data Entry | D23: ='Data Entry'!$D$119 -> 0 | E23: D119 | F23: D119 | G23: 1 | H23: 1 | I23: 1 | J23: 1
A24: APP_2_NAME_TUNED | B24: 15 | C24: Industry | D24: =Industry!$D$69 -> 0 | E24: D69 | F24: D69 | G24: 1 | H24: 1 | I24: 1 | J24: 1
A25: APP_3_AVG_RATE | B25: 14 | C25: Price Make-up | D25: ='Price Make-up'!$CT$134 -> 0 | E25: CT134 | F25: CT134 | G25: 1 | H25: 1 | I25: 1 | J25: 1
A26: APP_3_HOURS | B26: 3 | C26: Data Entry | D26: ='Data Entry'!$E$120 -> 0 | E26: E120 | F26: E120 | G26: 1 | H26: 1 | I26: 1 | J26: 1
A27: APP_3_HOURS_TUNED | B27: 15 | C27: Industry | D27: =Industry!$D$72 -> 0 | E27: D72 | F27: D72 | G27: 1 | H27: 1 | I27: 1 | J27: 1
A28: APP_3_HOURS_UNITS | B28: 3 | C28: Data Entry | D28: ='Data Entry'!$F$120 -> 0 | E28: F120 | F28: F120 | G28: 1 | H28: 1 | I28: 1 | J28: 1
A29: APP_3_NAME | B29: 3 | C29: Data Entry | D29: ='Data Entry'!$D$120 -> 0 | E29: D120 | F29: D120 | G29: 1 | H29: 1 | I29: 1 | J29: 1
A30: APP_3_NAME_TUNED | B30: 15 | C30: Industry | D30: =Industry!$D$71 -> 0 | E30: D71 | F30: D71 | G30: 1 | H30: 1 | I30: 1 | J30: 1
A31: APP_4_AVG_RATE | B31: 14 | C31: Price Make-up | D31: ='Price Make-up'!$CT$135 -> 0 | E31: CT135 | F31: CT135 | G31: 1 | H31: 1 | I31: 1 | J31: 1
A32: APP_4_HOURS | B32: 3 | C32: Data Entry | D32: ='Data Entry'!$E$121 -> 0 | E32: E121 | F32: E121 | G32: 1 | H32: 1 | I32: 1 | J32: 1
A33: APP_4_HOURS_TUNED | B33: 15 | C33: Industry | D33: =Industry!$D$74 -> 0 | E33: D74 | F33: D74 | G33: 1 | H33: 1 | I33: 1 | J33: 1
A34: APP_4_HOURS_UNITS | B34: 3 | C34: Data Entry | D34: ='Data Entry'!$F$121 -> 0 | E34: F121 | F34: F121 | G34: 1 | H34: 1 | I34: 1 | J34: 1
A35: APP_4_NAME | B35: 3 | C35: Data Entry | D35: ='Data Entry'!$D$121 -> 0 | E35: D121 | F35: D121 | G35: 1 | H35: 1 | I35: 1 | J35: 1
A36: APP_4_NAME_TUNED | B36: 15 | C36: Industry | D36: =Industry!$D$73 -> 0 | E36: D73 | F36: D73 | G36: 1 | H36: 1 | I36: 1 | J36: 1
A37: APP_5_AVG_RATE | B37: 14 | C37: Price Make-up | D37: ='Price Make-up'!$CT$136 -> 0 | E37: CT136 | F37: CT136 | G37: 1 | H37: 1 | I37: 1 | J37: 1
A38: APP_5_HOURS | B38: 3 | C38: Data Entry | D38: ='Data Entry'!$E$122 -> 0 | E38: E122 | F38: E122 | G38: 1 | H38: 1 | I38: 1 | J38: 1
A39: APP_5_HOURS_TUNED | B39: 15 | C39: Industry | D39: =Industry!$D$76 -> 0 | E39: D76 | F39: D76 | G39: 1 | H39: 1 | I39: 1 | J39: 1
A40: APP_5_HOURS_UNITS | B40: 3 | C40: Data Entry | D40: ='Data Entry'!$F$122 -> 0 | E40: F122 | F40: F122 | G40: 1 | H40: 1 | I40: 1 | J40: 1
...

Sheet Skipped_Ranges
A1: name | B1: sheet_id | C1: sheet_name | D1: ref_a1 | E1: first_cell | F1: last_cell | G1: n_rows | H1: n_cols | I1: n_cells | J1: reason
A2: COUNTRY_TABLE_START | B2: 17 | C2: World Cost tables | D2: ='World Cost tables'!$F$24 -> 0 | E2: F24 | F2: F24 | G2: 1 | H2: 1 | I2: 1 | J2: excel internal / system artifact
A3: CURRENCY_LOC_TABLE_START | B3: 19 | C3: World Currency Table | D3: ='World Currency Table'!$A$4 -> 0 | E3: A4 | F3: A4 | G3: 1 | H3: 1 | I3: 1 | J3: excel internal / system artifact
A4: CURRENCY_REM_TABLE_START | B4: 19 | C4: World Currency Table | D4: ='World Currency Table'!$A$2 -> 0 | E4: A2 | F4: A2 | G4: 1 | H4: 1 | I4: 1 | J4: excel internal / system artifact
A5: CUSTOMER_TYPE_TABLE_START | B5: 15 | C5: Industry | D5: =Industry!$D$4 -> 0 | E5: D4 | F5: D4 | G5: 1 | H5: 1 | I5: 1 | J5: excel internal / system artifact
A6: CUSTOMER_TYPE_TOOLKIT_TABLE_START | B6: 16 | C6: Toolkit | D6: =Toolkit!$E$11 -> 0 | E6: E11 | F6: E11 | G6: 1 | H6: 1 | I6: 1 | J6: excel internal / system artifact
A7: INDUSTRY_TABLE_START | B7: 15 | C7: Industry | D7: =Industry!$D$9 -> 0 | E7: D9 | F7: D9 | G7: 1 | H7: 1 | I7: 1 | J7: excel internal / system artifact
